Workbook

Sheet Sheet1
A2: 01/09 - 04/09 | J2: Uber
A3: 1 | B3: 46266 | C3: Ashan | D3: 1 | E3: 132CA | F3: Rs950.00 | G3: teriyaki rice | J3: PickMe
A4: 2 | B4: 46266 | C4: Corrine | D4: 2 | E4: pick-up | F4: Rs1,300.00 | G4: teriyaki rce | J4: Pick-up
A5: 3 | B5: 46266 | C5: Lakshan | D5: 2.5 | E5: pick-up | F5: Rs1,300.00 | G5: teriyaki 250
A6: 4 | B6: 46266 | C6: Gas | D6: 1 | E6: pick-up | F6: Rs650.00 | G6: teriyaki rice
A7: 5 | B7: 46266 | C7: Jithendra | D7: 3 | E7: pick-up | F7: Rs1,950.00 | G7: thai rice x3
A8: 6 | B8: 46266 | C8: Milinda | D8: 1 | E8: 05BF8 | F8: Rs950.00 | G8: teriyaki rice
A9: 7 | B9: 46266 | C9: Naveen | D9: 1 | E9: pick-up | F9: Rs650.00 | G9: teriyaki rice
A10: 8 | B10: 46266 | C10: Customer | D10: 1 | E10: pick-up | F10: Rs650.00 | G10: teriyaki rice | J10: Week 1 | K10: 106.5
A11: 9 | B11: 46266 | C11: Daham | D11: 1 | E11: 4EB3E | F11: Rs950.00 | G11: teriyaki rice | J11: Week 2 | K11: 104
A12: 10 | B12: 46266 | C12: Anuradha | D12: 2 | E12: pick-up | F12: Rs1,300.00 | G12: teriyaki rice x 2 | J12: Week 3 | K12: 131
A13: 11 | B13: 46266 | C13: Ranidu | D13: 1 | E13: 34D9C | F13: Rs950.00 | G13: teriyaki rice | J13: Week 4 | K13: 156
A14: 12 | B14: 46266 | C14: Naveen | D14: 2 | E14: pick-up | F14: Rs1,200.00 | G14: teriyaki 100, thai rice | J14: Week 5 | K14: 50
A15: 13 | B15: 46266 | C15: Meshal | D15: 1 | E15: E71FD | F15: Rs950.00 | G15: teriyki rice | H15: 19.5 | J15: Total sales | K15: 547.5
A16: 1 | B16: 46267 | C16: Ashan | D16: 1 | E16: pick-up | F16: Rs650.00 | G16: teriyaki rice
A17: 2 | B17: 46267 | C17: Laskhan | D17: 4 | E17: pick-up | F17: Rs2,100.00 | G17: teriyaki 250, thai 150
A18: 3 | B18: 46267 | C18: Chanud | D18: 1 | E18: 182399514 | F18: Rs950.00 | G18: thai rice
A19: 4 | B19: 46285 | C19: Walk-in | D19: 2 | E19: pick-up | F19: Rs1,300.00 | G19: thai rice, teriyaki rice
A20: 5 | B20: 46285 | C20: Danielle | D20: 1 | E20: 6B78C | F20: Rs800.00 | G20: teriyaki 100
A21: 6 | B21: 46267 | C21: Rajitha | D21: 1 | E21: 5D4BE | F21: Rs950.00 | G21: teriyaki rice
A22: 7 | B22: 46267 | C22: Mhmd | D22: 1 | E22: 182393526 | F22: Rs950.00 | G22: teriyaki rice
A23: 8 | B23: 46267 | C23: Shakila | D23: 1 | E23: pick-up | F23: Rs650.00 | G23: teriyaki rice
A24: 9 | B24: 46267 | C24: Meshal | D24: 1 | E24: 83422 | F24: Rs950.00 | G24: thai rice
A25: 10 | B25: 46267 | C25: Hensman | D25: 1 | E25: pick-up | F25: Rs650.00 | G25: teriyaki rice
A26: 11 | B26: 46267 | C26: Abishek | D26: 3 | E26: pick-up | F26: Rs1,800.00 | G26: thai rice x 2, vanilla shake
A27: 12 | B27: 46267 | C27: Dinusha | D27: 2 | E27: 4A315 | F27: Rs1,750.00 | G27: teriyaki rice, teriyaki 100
A28: 13 | B28: 46285 | C28: Tharindu | D28: 2 | E28: 86079 | F28: Rs1,750.00 | G28: teriyaki 100, thai rice
A29: 14 | B29: 46285 | C29: Promod | D29: 1 | E29: pick-up | F29: Rs650.00 | G29: teriykai rice
A30: 15 | B30: 46267 | C30: Lahiru | D30: 1 | E30: pick-up | F30: Rs650.00 | G30: teriyaki rice
A31: 16 | B31: 46267 | C31: Naveen | D31: 1 | E31: pick-up | F31: Rs650.00 | G31: teriyaki rice
A32: 17 | B32: 46267 | C32: Walk-in | D32: 1 | E32: pick-up | F32: Rs650.00 | G32: thai rice
A33: 18 | B33: 46267 | C33: Walk-in | D33: 1 | E33: pick-up | F33: Rs550.00 | G33: teriyaki 100
A34: 19 | B34: 46285 | C34: Randika | D34: 1 | E34: pick-up | F34: Rs550.00 | G34: teriyaki 100
A35: 20 | B35: 46267 | C35: Madhu | D35: 1 | E35: ED5F0 | F35: Rs950.00 | G35: teriyaki rice
A36: 21 | B36: 46267 | C36: Shavio | D36: 3 | E36: pick-up | F36: Rs1,750.00 | G36: teriyaki 100x2, thai rice
A37: 22 | B37: 46267 | C37: Bashith | D37: 2 | E37: pick-up | F37: Rs1,150.00 | G37: teriyaki rice, chocolate shake | H37: 33
A38: 1 | B38: 46268 | C38: Priyadarshana | D38: 1 | E38: 5533C | F38: Rs800.00 | G38: teriyaki 100
A39: 2 | B39: 46268 | C39: Lakshan | D39: 4 | E39: pick-up | F39: Rs2,100.00 | G39: teriyaki 250, thai 150
A40: 3 | B40: 46268 | C40: Tharushi | D40: 1 | E40: 182427010 | F40: Rs950.00 | G40: teriyaki rice
A41: 4 | B41: 46268 | C41: Chaya | D41: 1 | E41: 182427690 | F41: Rs950.00 | G41: thai rice
...

Sheet September Report
A1: SEPTEMBER SALES REPORT
A2: Pickup, Uber & PickMe | 1–29 September 2026 | 336 recorded orders
A3: TOTAL SALES | E3: ORDERS | I3: QUANTITY | M3: AVG ORDER
A4: =SUM('September Detail'!F2:F337) -> 421310 | E4: =COUNTA('September Detail'!A2:A337) -> 336 | I4: =SUM('September Detail'!E2:E337) -> 557.5 | M4: =A4/E4 -> 1253.8988
A6: Channel | B6: Orders | C6: Sales (LKR) | D6: Quantity | E6: Avg Order | F6: Sales Share
A7: Pickup | B7: =COUNTIF('September Detail'!$D$2:$D$337,A7) -> 163 | C7: =SUMIF('September Detail'!$D$2:$D$337,A7,'September Detail'!$F$2:$F$337) -> 192120 | D7: =SUMIF('September Detail'!$D$2:$D$337,A7,'September Detail'!$E$2:$E$337) -> 312.5 | E7: =IFERROR(C7/B7,0) -> 1178.6503 | F7: =IFERROR(C7/$C$10,0) -> 0.45600627
A8: Uber | B8: =COUNTIF('September Detail'!$D$2:$D$337,A8) -> 146 | C8: =SUMIF('September Detail'!$D$2:$D$337,A8,'September Detail'!$F$2:$F$337) -> 198800 | D8: =SUMIF('September Detail'!$D$2:$D$337,A8,'September Detail'!$E$2:$E$337) -> 213 | E8: =IFERROR(C8/B8,0) -> 1361.6438 | F8: =IFERROR(C8/$C$10,0) -> 0.47186157
A9: PickMe | B9: =COUNTIF('September Detail'!$D$2:$D$337,A9) -> 27 | C9: =SUMIF('September Detail'!$D$2:$D$337,A9,'September Detail'!$F$2:$F$337) -> 30390 | D9: =SUMIF('September Detail'!$D$2:$D$337,A9,'September Detail'!$E$2:$E$337) -> 32 | E9: =IFERROR(C9/B9,0) -> 1125.5556 | F9: =IFERROR(C9/$C$10,0) -> 0.072132159
A10: Total | B10: =SUM(B7:B9) -> 336 | C10: =SUM(C7:C9) -> 421310 | D10: =SUM(D7:D9) -> 557.5 | E10: =IFERROR(C10/B10,0) -> 1253.8988 | F10: =SUM(F7:F9) -> 1
A13: Period | B13: Pickup | C13: Uber | D13: PickMe | E13: Total Sales | F13: Orders
A14: 1–6 Sep | B14: =SUMIFS('September Detail'!$F$2:$F$337,'September Detail'!$D$2:$D$337,"Pickup",'September Detail'!$B$2:$B$337,">="&DATE(2026,9,1),'September Detail'!$B$2:$B$337,"<="&DATE(2026,9,6)) -> 39600 | C14: =SUMIFS('September Detail'!$F$2:$F$337,'September Detail'!$D$2:$D$337,"Uber",'September Detail'!$B$2:$B$337,">="&DATE(2026,9,1),'September Detail'!$B$2:$B$337,"<="&DATE(2026,9,6)) -> 25840 | D14: =SUMIFS('September Detail'!$F$2:$F$337,'September Detail'!$D$2:$D$337,"PickMe",'September Detail'!$B$2:$B$337,">="&DATE(2026,9,1),'September Detail'!$B$2:$B$337,"<="&DATE(2026,9,6)) -> 5550 | E14: =SUM(B14:D14) -> 70990 | F14: =COUNTIFS('September Detail'!$B$2:$B$337,">="&DATE(2026,9,1),'September Detail'!$B$2:$B$337,"<="&DATE(2026,9,6)) -> 63
A15: 7–13 Sep | B15: =SUMIFS('September Detail'!$F$2:$F$337,'September Detail'!$D$2:$D$337,"Pickup",'September Detail'!$B$2:$B$337,">="&DATE(2026,9,7),'September Detail'!$B$2:$B$337,"<="&DATE(2026,9,13)) -> 27800 | C15: =SUMIFS('September Detail'!$F$2:$F$337,'September Detail'!$D$2:$D$337,"Uber",'September Detail'!$B$2:$B$337,">="&DATE(2026,9,7),'September Detail'!$B$2:$B$337,"<="&DATE(2026,9,13)) -> 41100 | D15: =SUMIFS('September Detail'!$F$2:$F$337,'September Detail'!$D$2:$D$337,"PickMe",'September Detail'!$B$2:$B$337,">="&DATE(2026,9,7),'September Detail'!$B$2:$B$337,"<="&DATE(2026,9,13)) -> 5400 | E15: =SUM(B15:D15) -> 74300 | F15: =COUNTIFS('September Detail'!$B$2:$B$337,">="&DATE(2026,9,7),'September Detail'!$B$2:$B$337,"<="&DATE(2026,9,13)) -> 59
A16: 14–20 Sep | B16: =SUMIFS('September Detail'!$F$2:$F$337,'September Detail'!$D$2:$D$337,"Pickup",'September Detail'!$B$2:$B$337,">="&DATE(2026,9,14),'September Detail'!$B$2:$B$337,"<="&DATE(2026,9,20)) -> 51220 | C16: =SUMIFS('September Detail'!$F$2:$F$337,'September Detail'!$D$2:$D$337,"Uber",'September Detail'!$B$2:$B$337,">="&DATE(2026,9,14),'September Detail'!$B$2:$B$337,"<="&DATE(2026,9,20)) -> 48760 | D16: =SUMIFS('September Detail'!$F$2:$F$337,'September Detail'!$D$2:$D$337,"PickMe",'September Detail'!$B$2:$B$337,">="&DATE(2026,9,14),'September Detail'!$B$2:$B$337,"<="&DATE(2026,9,20)) -> 7200 | E16: =SUM(B16:D16) -> 107180 | F16: =COUNTIFS('September Detail'!$B$2:$B$337,">="&DATE(2026,9,14),'September Detail'!$B$2:$B$337,"<="&DATE(2026,9,20)) -> 79
A17: 21–27 Sep | B17: =SUMIFS('September Detail'!$F$2:$F$337,'September Detail'!$D$2:$D$337,"Pickup",'September Detail'!$B$2:$B$337,">="&DATE(2026,9,21),'September Detail'!$B$2:$B$337,"<="&DATE(2026,9,27)) -> 55740 | C17: =SUMIFS('September Detail'!$F$2:$F$337,'September Detail'!$D$2:$D$337,"Uber",'September Detail'!$B$2:$B$337,">="&DATE(2026,9,21),'September Detail'!$B$2:$B$337,"<="&DATE(2026,9,27)) -> 59610 | D17: =SUMIFS('September Detail'!$F$2:$F$337,'September Detail'!$D$2:$D$337,"PickMe",'September Detail'!$B$2:$B$337,">="&DATE(2026,9,21),'September Detail'!$B$2:$B$337,"<="&DATE(2026,9,27)) -> 10640 | E17: =SUM(B17:D17) -> 125990 | F17: =COUNTIFS('September Detail'!$B$2:$B$337,">="&DATE(2026,9,21),'September Detail'!$B$2:$B$337,"<="&DATE(2026,9,27)) -> 100
A18: 28–30 Sep | B18: =SUMIFS('September Detail'!$F$2:$F$337,'September Detail'!$D$2:$D$337,"Pickup",'September Detail'!$B$2:$B$337,">="&DATE(2026,9,28),'September Detail'!$B$2:$B$337,"<="&DATE(2026,9,30)) -> 17760 | C18: =SUMIFS('September Detail'!$F$2:$F$337,'September Detail'!$D$2:$D$337,"Uber",'September Detail'!$B$2:$B$337,">="&DATE(2026,9,28),'September Detail'!$B$2:$B$337,"<="&DATE(2026,9,30)) -> 23490 | D18: =SUMIFS('September Detail'!$F$2:$F$337,'September Detail'!$D$2:$D$337,"PickMe",'September Detail'!$B$2:$B$337,">="&DATE(2026,9,28),'September Detail'!$B$2:$B$337,"<="&DATE(2026,9,30)) -> 1600 | E18: =SUM(B18:D18) -> 42850 | F18: =COUNTIFS('September Detail'!$B$2:$B$337,">="&DATE(2026,9,28),'September Detail'!$B$2:$B$337,"<="&DATE(2026,9,30)) -> 35
A19: Total | B19: =SUM(B14:B18) -> 192120 | C19: =SUM(C14:C18) -> 198800 | D19: =SUM(D14:D18) -> 30390 | E19: =SUM(E14:E18) -> 421310 | F19: =SUM(F14:F18) -> 336
A22: Date | B22: Pickup | C22: Uber | D22: PickMe | E22: Total Sales | F22: Orders
A23: 46266 | B23: =SUMIFS('September Detail'!$F$2:$F$337,'September Detail'!$D$2:$D$337,"Pickup",'September Detail'!$B$2:$B$337,$A23) -> 9000 | C23: =SUMIFS('September Detail'!$F$2:$F$337,'September Detail'!$D$2:$D$337,"Uber",'September Detail'!$B$2:$B$337,$A23) -> 4750 | D23: =SUMIFS('September Detail'!$F$2:$F$337,'September Detail'!$D$2:$D$337,"PickMe",'September Detail'!$B$2:$B$337,$A23) -> 0 | E23: =SUM(B23:D23) -> 13750 | F23: =COUNTIF('September Detail'!$B$2:$B$337,$A23) -> 13
A24: 46267 | B24: =SUMIFS('September Detail'!$F$2:$F$337,'September Detail'!$D$2:$D$337,"Pickup",'September Detail'!$B$2:$B$337,$A24) -> 11250 | C24: =SUMIFS('September Detail'!$F$2:$F$337,'September Detail'!$D$2:$D$337,"Uber",'September Detail'!$B$2:$B$337,$A24) -> 4600 | D24: =SUMIFS('September Detail'!$F$2:$F$337,'September Detail'!$D$2:$D$337,"PickMe",'September Detail'!$B$2:$B$337,$A24) -> 1900 | E24: =SUM(B24:D24) -> 17750 | F24: =COUNTIF('September Detail'!$B$2:$B$337,$A24) -> 17
A25: 46268 | B25: =SUMIFS('September Detail'!$F$2:$F$337,'September Detail'!$D$2:$D$337,"Pickup",'September Detail'!$B$2:$B$337,$A25) -> 8400 | C25: =SUMIFS('September Detail'!$F$2:$F$337,'September Detail'!$D$2:$D$337,"Uber",'September Detail'!$B$2:$B$337,$A25) -> 7300 | D25: =SUMIFS('September Detail'!$F$2:$F$337,'September Detail'!$D$2:$D$337,"PickMe",'September Detail'!$B$2:$B$337,$A25) -> 2850 | E25: =SUM(B25:D25) -> 18550 | F25: =COUNTIF('September Detail'!$B$2:$B$337,$A25) -> 17
A26: 46269 | B26: =SUMIFS('September Detail'!$F$2:$F$337,'September Detail'!$D$2:$D$337,"Pickup",'September Detail'!$B$2:$B$337,$A26) -> 10950 | C26: =SUMIFS('September Detail'!$F$2:$F$337,'September Detail'!$D$2:$D$337,"Uber",'September Detail'!$B$2:$B$337,$A26) -> 9190 | D26: =SUMIFS('September Detail'!$F$2:$F$337,'September Detail'!$D$2:$D$337,"PickMe",'September Detail'!$B$2:$B$337,$A26) -> 800 | E26: =SUM(B26:D26) -> 20940 | F26: =COUNTIF('September Detail'!$B$2:$B$337,$A26) -> 16
A27: 46272 | B27: =SUMIFS('September Detail'!$F$2:$F$337,'September Detail'!$D$2:$D$337,"Pickup",'September Detail'!$B$2:$B$337,$A27) -> 5800 | C27: =SUMIFS('September Detail'!$F$2:$F$337,'September Detail'!$D$2:$D$337,"Uber",'September Detail'!$B$2:$B$337,$A27) -> 14450 | D27: =SUMIFS('September Detail'!$F$2:$F$337,'September Detail'!$D$2:$D$337,"PickMe",'September Detail'!$B$2:$B$337,$A27) -> 0 | E27: =SUM(B27:D27) -> 20250 | F27: =COUNTIF('September Detail'!$B$2:$B$337,$A27) -> 18
A28: 46273 | B28: =SUMIFS('September Detail'!$F$2:$F$337,'September Detail'!$D$2:$D$337,"Pickup",'September Detail'!$B$2:$B$337,$A28) -> 9600 | C28: =SUMIFS('September Detail'!$F$2:$F$337,'September Detail'!$D$2:$D$337,"Uber",'September Detail'!$B$2:$B$337,$A28) -> 4600 | D28: =SUMIFS('September Detail'!$F$2:$F$337,'September Detail'!$D$2:$D$337,"PickMe",'September Detail'!$B$2:$B$337,$A28) -> 2700 | E28: =SUM(B28:D28) -> 16900 | F28: =COUNTIF('September Detail'!$B$2:$B$337,$A28) -> 12
A29: 46274 | B29: =SUMIFS('September Detail'!$F$2:$F$337,'September Detail'!$D$2:$D$337,"Pickup",'September Detail'!$B$2:$B$337,$A29) -> 6550 | C29: =SUMIFS('September Detail'!$F$2:$F$337,'September Detail'!$D$2:$D$337,"Uber",'September Detail'!$B$2:$B$337,$A29) -> 8100 | D29: =SUMIFS('September Detail'!$F$2:$F$337,'September Detail'!$D$2:$D$337,"PickMe",'September Detail'!$B$2:$B$337,$A29) -> 2700 | E29: =SUM(B29:D29) -> 17350 | F29: =COUNTIF('September Detail'!$B$2:$B$337,$A29) -> 17
A30: 46276 | B30: =SUMIFS('September Detail'!$F$2:$F$337,'September Detail'!$D$2:$D$337,"Pickup",'September Detail'!$B$2:$B$337,$A30) -> 5850 | C30: =SUMIFS('September Detail'!$F$2:$F$337,'September Detail'!$D$2:$D$337,"Uber",'September Detail'!$B$2:$B$337,$A30) -> 13950 | D30: =SUMIFS('September Detail'!$F$2:$F$337,'September Detail'!$D$2:$D$337,"PickMe",'September Detail'!$B$2:$B$337,$A30) -> 0 | E30: =SUM(B30:D30) -> 19800 | F30: =COUNTIF('September Detail'!$B$2:$B$337,$A30) -> 12
A31: 46279 | B31: =SUMIFS('September Detail'!$F$2:$F$337,'September Detail'!$D$2:$D$337,"Pickup",'September Detail'!$B$2:$B$337,$A31) -> 8950 | C31: =SUMIFS('September Detail'!$F$2:$F$337,'September Detail'!$D$2:$D$337,"Uber",'September Detail'!$B$2:$B$337,$A31) -> 5400 | D31: =SUMIFS('September Detail'!$F$2:$F$337,'September Detail'!$D$2:$D$337,"PickMe",'September Detail'!$B$2:$B$337,$A31) -> 4450 | E31: =SUM(B31:D31) -> 18800 | F31: =COUNTIF('September Detail'!$B$2:$B$337,$A31) -> 15
A32: 46280 | B32: =SUMIFS('September Detail'!$F$2:$F$337,'September Detail'!$D$2:$D$337,"Pickup",'September Detail'!$B$2:$B$337,$A32) -> 8250 | C32: =SUMIFS('September Detail'!$F$2:$F$337,'September Detail'!$D$2:$D$337,"Uber",'September Detail'!$B$2:$B$337,$A32) -> 11750 | D32: =SUMIFS('September Detail'!$F$2:$F$337,'September Detail'!$D$2:$D$337,"PickMe",'September Detail'!$B$2:$B$337,$A32) -> 850 | E32: =SUM(B32:D32) -> 20850 | F32: =COUNTIF('September Detail'!$B$2:$B$337,$A32) -> 14
A33: 46281 | B33: =SUMIFS('September Detail'!$F$2:$F$337,'September Detail'!$D$2:$D$337,"Pickup",'September Detail'!$B$2:$B$337,$A33) -> 12760 | C33: =SUMIFS('September Detail'!$F$2:$F$337,'September Detail'!$D$2:$D$337,"Uber",'September Detail'!$B$2:$B$337,$A33) -> 9350 | D33: =SUMIFS('September Detail'!$F$2:$F$337,'September Detail'!$D$2:$D$337,"PickMe",'September Detail'!$B$2:$B$337,$A33) -> 1900 | E33: =SUM(B33:D33) -> 24010 | F33: =COUNTIF('September Detail'!$B$2:$B$337,$A33) -> 20
A34: 46282 | B34: =SUMIFS('September Detail'!$F$2:$F$337,'September Detail'!$D$2:$D$337,"Pickup",'September Detail'!$B$2:$B$337,$A34) -> 7880 | C34: =SUMIFS('September Detail'!$F$2:$F$337,'September Detail'!$D$2:$D$337,"Uber",'September Detail'!$B$2:$B$337,$A34) -> 8610 | D34: =SUMIFS('September Detail'!$F$2:$F$337,'September Detail'!$D$2:$D$337,"PickMe",'September Detail'!$B$2:$B$337,$A34) -> 0 | E34: =SUM(B34:D34) -> 16490 | F34: =COUNTIF('September Detail'!$B$2:$B$337,$A34) -> 13
... A43: 46294 | B43: =SUMIFS('September Detail'!$F$2:$F$337,'September Detail'!$D$2:$D$337,"Pickup",'September Detail'!$B$2:$B$337,$A43) -> 9940 | C43: =SUMIFS('September Detail'!$F$2:$F$337,'September Detail'!$D$2:$D$337,"Uber",'September Detail'!$B$2:$B$337,$A43) -> 9990 | D43: =SUMIFS('September Detail'!$F$2:$F$337,'September Detail'!$D$2:$D$337,"PickMe",'September Detail'!$B$2:$B$337,$A43) -> 650 | E43: =SUM(B43:D43) -> 20580 | F43: =COUNTIF('September Detail'!$B$2:$B$337,$A43) -> 16
A44: Total | B44: =SUM(B23:B43) -> 192120 | C44: =SUM(C23:C43) -> 198800 | D44: =SUM(D23:D43) -> 30390 | E44: =SUM(E23:E43) -> 421310 | F44: =SUM(F23:F43) -> 336
A47: SEPTEMBER PRODUCT QUANTITY MIX
A48: Category | B48: Quantity
A49: Teriyaki Rice | B49: 216
A50: Teriyaki (chicken) | B50: 118
A51: Thai Rice | B51: 96
A53: Milkshake | B53: 53
A54: Other | B54: 35
A55: Total | B55: 518
A57: Method: items separated by commas; x2/x3 multipliers applied; items without a multiplier counted as 1. Teriyaki Rice contains descriptions with both ‘teriyaki’ and ‘rice’; Teriyaki contains non-rice teriyaki portions. Chicken includes only descriptions explicitly containing ‘chicken’.

Sheet September Detail
A1: Source Row | B1: Date | C1: Customer | D1: Channel | E1: Quantity | F1: Sales (LKR) | G1: Items | H1: Order Reference
A2: 3 | B2: 46266 | C2: Ashan | D2: Uber | E2: 1 | F2: 950 | G2: teriyaki rice | H2: 132CA
A3: 4 | B3: 46266 | C3: Corrine | D3: Pickup | E3: 2 | F3: 1300 | G3: teriyaki rce | H3: pick-up
A4: 5 | B4: 46266 | C4: Lakshan | D4: Pickup | E4: 2.5 | F4: 1300 | G4: teriyaki 250 | H4: pick-up
A5: 6 | B5: 46266 | C5: Gas | D5: Pickup | E5: 1 | F5: 650 | G5: teriyaki rice | H5: pick-up
A6: 7 | B6: 46266 | C6: Jithendra | D6: Pickup | E6: 3 | F6: 1950 | G6: thai rice x3 | H6: pick-up
A7: 8 | B7: 46266 | C7: Milinda | D7: Uber | E7: 1 | F7: 950 | G7: teriyaki rice | H7: 05BF8
A8: 9 | B8: 46266 | C8: Naveen | D8: Pickup | E8: 1 | F8: 650 | G8: teriyaki rice | H8: pick-up
A9: 10 | B9: 46266 | C9: Customer | D9: Pickup | E9: 1 | F9: 650 | G9: teriyaki rice | H9: pick-up
A10: 11 | B10: 46266 | C10: Daham | D10: Uber | E10: 1 | F10: 950 | G10: teriyaki rice | H10: 4EB3E
A11: 12 | B11: 46266 | C11: Anuradha | D11: Pickup | E11: 2 | F11: 1300 | G11: teriyaki rice x 2 | H11: pick-up
A12: 13 | B12: 46266 | C12: Ranidu | D12: Uber | E12: 1 | F12: 950 | G12: teriyaki rice | H12: 34D9C
A13: 14 | B13: 46266 | C13: Naveen | D13: Pickup | E13: 2 | F13: 1200 | G13: teriyaki 100, thai rice | H13: pick-up
... A16: 17 | B16: 46267 | C16: Laskhan | D16: Pickup | E16: 4 | F16: 2100 | G16: teriyaki 250, thai 150 | H16: pick-up
A17: 18 | B17: 46267 | C17: Chanud | D17: PickMe | E17: 1 | F17: 950 | G17: thai rice | H17: 182399514
A18: 19 | B18: 46285 | C18: Walk-in | D18: Pickup | E18: 2 | F18: 1300 | G18: thai rice, teriyaki rice | H18: pick-up
A19: 20 | B19: 46285 | C19: Danielle | D19: Uber | E19: 1 | F19: 800 | G19: teriyaki 100 | H19: 6B78C
A20: 21 | B20: 46267 | C20: Rajitha | D20: Uber | E20: 1 | F20: 950 | G20: teriyaki rice | H20: 5D4BE
A21: 22 | B21: 46267 | C21: Mhmd | D21: PickMe | E21: 1 | F21: 950 | G21: teriyaki rice | H21: 182393526
A22: 23 | B22: 46267 | C22: Shakila | D22: Pickup | E22: 1 | F22: 650 | G22: teriyaki rice | H22: pick-up
A23: 24 | B23: 46267 | C23: Meshal | D23: Uber | E23: 1 | F23: 950 | G23: thai rice | H23: 83422
A24: 25 | B24: 46267 | C24: Hensman | D24: Pickup | E24: 1 | F24: 650 | G24: teriyaki rice | H24: pick-up
A25: 26 | B25: 46267 | C25: Abishek | D25: Pickup | E25: 3 | F25: 1800 | G25: thai rice x 2, vanilla shake | H25: pick-up
A26: 27 | B26: 46267 | C26: Dinusha | D26: Uber | E26: 2 | F26: 1750 | G26: teriyaki rice, teriyaki 100 | H26: 4A315
A27: 28 | B27: 46285 | C27: Tharindu | D27: Uber | E27: 2 | F27: 1750 | G27: teriyaki 100, thai rice | H27: 86079
A28: 29 | B28: 46285 | C28: Promod | D28: Pickup | E28: 1 | F28: 650 | G28: teriykai rice | H28: pick-up
A29: 30 | B29: 46267 | C29: Lahiru | D29: Pickup | E29: 1 | F29: 650 | G29: teriyaki rice | H29: pick-up
A30: 31 | B30: 46267 | C30: Naveen | D30: Pickup | E30: 1 | F30: 650 | G30: teriyaki rice | H30: pick-up
A31: 32 | B31: 46267 | C31: Walk-in | D31: Pickup | E31: 1 | F31: 650 | G31: thai rice | H31: pick-up
A32: 33 | B32: 46267 | C32: Walk-in | D32: Pickup | E32: 1 | F32: 550 | G32: teriyaki 100 | H32: pick-up
A33: 34 | B33: 46285 | C33: Randika | D33: Pickup | E33: 1 | F33: 550 | G33: teriyaki 100 | H33: pick-up
A34: 35 | B34: 46267 | C34: Madhu | D34: Uber | E34: 1 | F34: 950 | G34: teriyaki rice | H34: ED5F0
A35: 36 | B35: 46267 | C35: Shavio | D35: Pickup | E35: 3 | F35: 1750 | G35: teriyaki 100x2, thai rice | H35: pick-up
A36: 37 | B36: 46267 | C36: Bashith | D36: Pickup | E36: 2 | F36: 1150 | G36: teriyaki rice, chocolate shake | H36: pick-up
A37: 38 | B37: 46268 | C37: Priyadarshana | D37: Uber | E37: 1 | F37: 800 | G37: teriyaki 100 | H37: 5533C
A38: 39 | B38: 46268 | C38: Lakshan | D38: Pickup | E38: 4 | F38: 2100 | G38: teriyaki 250, thai 150 | H38: pick-up
A39: 40 | B39: 46268 | C39: Tharushi | D39: PickMe | E39: 1 | F39: 950 | G39: teriyaki rice | H39: 182427010
A40: 41 | B40: 46268 | C40: Chaya | D40: PickMe | E40: 1 | F40: 950 | G40: thai rice | H40: 182427690
A41: 42 | B41: 46268 | C41: Roshan | D41: Pickup | E41: 1 | F41: 650 | G41: teriyaki rice | H41: pick-up
A42: 43 | B42: 46268 | C42: Dilip | D42: Pickup | E42: 2 | F42: 1300 | G42: teriyaki rice | H42: pick-up
...
